2017-03-29 16:21:52.038 29647 ERROR glance.api.v2.image_data Traceback (most recent call last):
2017-03-29 16:21:52.038 29647 ERROR glance.api.v2.image_data   File "/usr/local/lib/python2.7/dist-packages/glance/api/v2/image_data.py", line 116, in upload
2017-03-29 16:21:52.038 29647 ERROR glance.api.v2.image_data     image.set_data(data, size)
2017-03-29 16:21:52.038 29647 ERROR glance.api.v2.image_data   File "/usr/local/lib/python2.7/dist-packages/glance/domain/proxy.py", line 195, in set_data
2017-03-29 16:21:52.038 29647 ERROR glance.api.v2.image_data     self.base.set_data(data, size)
2017-03-29 16:21:52.038 29647 ERROR glance.api.v2.image_data   File "/usr/local/lib/python2.7/dist-packages/glance/notifier.py", line 480, in set_data
2017-03-29 16:21:52.038 29647 ERROR glance.api.v2.image_data     _send_notification(notify_error, 'image.upload', msg)
2017-03-29 16:21:52.038 29647 ERROR glance.api.v2.image_data   File "/usr/local/lib/python2.7/dist-packages/oslo_utils/excutils.py", line 220, in __exit__
2017-03-29 16:21:52.038 29647 ERROR glance.api.v2.image_data     self.force_reraise()
2017-03-29 16:21:52.038 29647 ERROR glance.api.v2.image_data   File "/usr/local/lib/python2.7/dist-packages/oslo_utils/excutils.py", line 196, in force_reraise
2017-03-29 16:21:52.038 29647 ERROR glance.api.v2.image_data     six.reraise(self.type_, self.value, self.tb)
2017-03-29 16:21:52.038 29647 ERROR glance.api.v2.image_data   File "/usr/local/lib/python2.7/dist-packages/glance/notifier.py", line 427, in set_data
2017-03-29 16:21:52.038 29647 ERROR glance.api.v2.image_data     self.repo.set_data(data, size)
2017-03-29 16:21:52.038 29647 ERROR glance.api.v2.image_data   File "/usr/local/lib/python2.7/dist-packages/glance/api/policy.py", line 192, in set_data
2017-03-29 16:21:52.038 29647 ERROR glance.api.v2.image_data     return self.image.set_data(*args, **kwargs)
2017-03-29 16:21:52.038 29647 ERROR glance.api.v2.image_data   File "/usr/local/lib/python2.7/dist-packages/glance/quota/__init__.py", line 304, in set_data
2017-03-29 16:21:52.038 29647 ERROR glance.api.v2.image_data     self.image.set_data(data, size=size)
2017-03-29 16:21:52.038 29647 ERROR glance.api.v2.image_data   File "/usr/local/lib/python2.7/dist-packages/glance/location.py", line 439, in set_data
2017-03-29 16:21:52.038 29647 ERROR glance.api.v2.image_data     verifier=verifier)
2017-03-29 16:21:52.038 29647 ERROR glance.api.v2.image_data   File "/usr/local/lib/python2.7/dist-packages/glance_store/backend.py", line 453, in add_to_backend
2017-03-29 16:21:52.038 29647 ERROR glance.api.v2.image_data     verifier)
2017-03-29 16:21:52.038 29647 ERROR glance.api.v2.image_data   File "/usr/local/lib/python2.7/dist-packages/glance_store/backend.py", line 426, in store_add_to_backend
2017-03-29 16:21:52.038 29647 ERROR glance.api.v2.image_data     verifier=verifier)
2017-03-29 16:21:52.038 29647 ERROR glance.api.v2.image_data   File "/usr/local/lib/python2.7/dist-packages/glance_store/capabilities.py", line 223, in op_checker
2017-03-29 16:21:52.038 29647 ERROR glance.api.v2.image_data     raise op_exec_map[op](**kwargs)
2017-03-29 16:21:52.038 29647 ERROR glance.api.v2.image_data StoreAddDisabled: Configuration for store failed. Adding images to this store is disabled.
2017-03-29 16:21:52.038 29647 ERROR glance.api.v2.image_data

