Mar 29 17:46:28 altocumulus01 nova-api[32263]: 2017-03-29 17:46:28.176 32263 CRITICAL nova [req-86fa5b80-dc2a-4987-bcda-08d5f5309c30 - - - - -] OSError: [Errno 13] Permission denied: '/usr/local/lib/python2.7/dist-packages/keys'
Mar 29 17:46:28 altocumulus01 nova-api[32263]: 2017-03-29 17:46:28.176 32263 ERROR nova Traceback (most recent call last):
Mar 29 17:46:28 altocumulus01 nova-api[32263]: 2017-03-29 17:46:28.176 32263 ERROR nova   File "/usr/local/bin/nova-api", line 10, in <module>
Mar 29 17:46:28 altocumulus01 nova-api[32263]: 2017-03-29 17:46:28.176 32263 ERROR nova     sys.exit(main())
Mar 29 17:46:28 altocumulus01 nova-api[32263]: 2017-03-29 17:46:28.176 32263 ERROR nova   File "/usr/local/lib/python2.7/dist-packages/nova/cmd/api.py", line 59, in main
Mar 29 17:46:28 altocumulus01 nova-api[32263]: 2017-03-29 17:46:28.176 32263 ERROR nova     server = service.WSGIService(api, use_ssl=should_use_ssl)
Mar 29 17:46:28 altocumulus01 nova-api[32263]: 2017-03-29 17:46:28.176 32263 ERROR nova   File "/usr/local/lib/python2.7/dist-packages/nova/service.py", line 311, in __init__
Mar 29 17:46:28 altocumulus01 nova-api[32263]: 2017-03-29 17:46:28.176 32263 ERROR nova     self.app = self.loader.load_app(name)
Mar 29 17:46:28 altocumulus01 nova-api[32263]: 2017-03-29 17:46:28.176 32263 ERROR nova   File "/usr/local/lib/python2.7/dist-packages/nova/wsgi.py", line 497, in load_app
Mar 29 17:46:28 altocumulus01 nova-api[32263]: 2017-03-29 17:46:28.176 32263 ERROR nova     return deploy.loadapp("config:%s" % self.config_path, name=name)
Mar 29 17:46:28 altocumulus01 nova-api[32263]: 2017-03-29 17:46:28.176 32263 ERROR nova   File "/usr/local/lib/python2.7/dist-packages/paste/deploy/loadwsgi.py", line 247, in loadapp
Mar 29 17:46:28 altocumulus01 nova-api[32263]: 2017-03-29 17:46:28.176 32263 ERROR nova     return loadobj(APP, uri, name=name, **kw)
Mar 29 17:46:28 altocumulus01 nova-api[32263]: 2017-03-29 17:46:28.176 32263 ERROR nova   File "/usr/local/lib/python2.7/dist-packages/paste/deploy/loadwsgi.py", line 272, in loadobj
Mar 29 17:46:28 altocumulus01 nova-api[32263]: 2017-03-29 17:46:28.176 32263 ERROR nova     return context.create()
Mar 29 17:46:28 altocumulus01 nova-api[32263]: 2017-03-29 17:46:28.176 32263 ERROR nova   File "/usr/local/lib/python2.7/dist-packages/paste/deploy/loadwsgi.py", line 710, in create
Mar 29 17:46:28 altocumulus01 nova-api[32263]: 2017-03-29 17:46:28.176 32263 ERROR nova     return self.object_type.invoke(self)
Mar 29 17:46:28 altocumulus01 nova-api[32263]: 2017-03-29 17:46:28.176 32263 ERROR nova   File "/usr/local/lib/python2.7/dist-packages/paste/deploy/loadwsgi.py", line 144, in invoke
Mar 29 17:46:28 altocumulus01 nova-api[32263]: 2017-03-29 17:46:28.176 32263 ERROR nova     **context.local_conf)
Mar 29 17:46:28 altocumulus01 nova-api[32263]: 2017-03-29 17:46:28.176 32263 ERROR nova   File "/usr/local/lib/python2.7/dist-packages/paste/deploy/util.py", line 55, in fix_call
Mar 29 17:46:28 altocumulus01 nova-api[32263]: 2017-03-29 17:46:28.176 32263 ERROR nova     val = callable(*args, **kw)
Mar 29 17:46:28 altocumulus01 nova-api[32263]: 2017-03-29 17:46:28.176 32263 ERROR nova   File "/usr/local/lib/python2.7/dist-packages/nova/api/openstack/urlmap.py", line 160, in urlmap_factory
Mar 29 17:46:28 altocumulus01 nova-api[32263]: 2017-03-29 17:46:28.176 32263 ERROR nova     app = loader.get_app(app_name, global_conf=global_conf)
Mar 29 17:46:28 altocumulus01 nova-api[32263]: 2017-03-29 17:46:28.176 32263 ERROR nova   File "/usr/local/lib/python2.7/dist-packages/paste/deploy/loadwsgi.py", line 350, in get_app
Mar 29 17:46:28 altocumulus01 nova-api[32263]: 2017-03-29 17:46:28.176 32263 ERROR nova     name=name, global_conf=global_conf).create()
Mar 29 17:46:28 altocumulus01 nova-api[32263]: 2017-03-29 17:46:28.176 32263 ERROR nova   File "/usr/local/lib/python2.7/dist-packages/paste/deploy/loadwsgi.py", line 710, in create
Mar 29 17:46:28 altocumulus01 nova-api[32263]: 2017-03-29 17:46:28.176 32263 ERROR nova     return self.object_type.invoke(self)
Mar 29 17:46:28 altocumulus01 nova-api[32263]: 2017-03-29 17:46:28.176 32263 ERROR nova   File "/usr/local/lib/python2.7/dist-packages/paste/deploy/loadwsgi.py", line 144, in invoke
Mar 29 17:46:28 altocumulus01 nova-api[32263]: 2017-03-29 17:46:28.176 32263 ERROR nova     **context.local_conf)
Mar 29 17:46:28 altocumulus01 nova-api[32263]: 2017-03-29 17:46:28.176 32263 ERROR nova   File "/usr/local/lib/python2.7/dist-packages/paste/deploy/util.py", line 55, in fix_call
Mar 29 17:46:28 altocumulus01 nova-api[32263]: 2017-03-29 17:46:28.176 32263 ERROR nova     val = callable(*args, **kw)
Mar 29 17:46:28 altocumulus01 nova-api[32263]: 2017-03-29 17:46:28.176 32263 ERROR nova   File "/usr/local/lib/python2.7/dist-packages/nova/api/auth.py", line 57, in pipeline_factory_v21
Mar 29 17:46:28 altocumulus01 nova-api[32263]: 2017-03-29 17:46:28.176 32263 ERROR nova     return _load_pipeline(loader, local_conf[CONF.api.auth_strategy].split())
Mar 29 17:46:28 altocumulus01 nova-api[32263]: 2017-03-29 17:46:28.176 32263 ERROR nova   File "/usr/local/lib/python2.7/dist-packages/nova/api/auth.py", line 38, in _load_pipeline
Mar 29 17:46:28 altocumulus01 nova-api[32263]: 2017-03-29 17:46:28.176 32263 ERROR nova     app = loader.get_app(pipeline[-1])
Mar 29 17:46:28 altocumulus01 nova-api[32263]: 2017-03-29 17:46:28.176 32263 ERROR nova   File "/usr/local/lib/python2.7/dist-packages/paste/deploy/loadwsgi.py", line 350, in get_app
Mar 29 17:46:28 altocumulus01 nova-api[32263]: 2017-03-29 17:46:28.176 32263 ERROR nova     name=name, global_conf=global_conf).create()
Mar 29 17:46:28 altocumulus01 nova-api[32263]: 2017-03-29 17:46:28.176 32263 ERROR nova   File "/usr/local/lib/python2.7/dist-packages/paste/deploy/loadwsgi.py", line 710, in create
Mar 29 17:46:28 altocumulus01 nova-api[32263]: 2017-03-29 17:46:28.176 32263 ERROR nova     return self.object_type.invoke(self)
Mar 29 17:46:28 altocumulus01 nova-api[32263]: 2017-03-29 17:46:28.176 32263 ERROR nova   File "/usr/local/lib/python2.7/dist-packages/paste/deploy/loadwsgi.py", line 146, in invoke
Mar 29 17:46:28 altocumulus01 nova-api[32263]: 2017-03-29 17:46:28.176 32263 ERROR nova     return fix_call(context.object, context.global_conf, **context.local_conf)
Mar 29 17:46:28 altocumulus01 nova-api[32263]: 2017-03-29 17:46:28.176 32263 ERROR nova   File "/usr/local/lib/python2.7/dist-packages/paste/deploy/util.py", line 55, in fix_call
Mar 29 17:46:28 altocumulus01 nova-api[32263]: 2017-03-29 17:46:28.176 32263 ERROR nova     val = callable(*args, **kw)
Mar 29 17:46:28 altocumulus01 nova-api[32263]: 2017-03-29 17:46:28.176 32263 ERROR nova   File "/usr/local/lib/python2.7/dist-packages/nova/api/openstack/__init__.py", line 218, in factory
Mar 29 17:46:28 altocumulus01 nova-api[32263]: 2017-03-29 17:46:28.176 32263 ERROR nova     return cls()
Mar 29 17:46:28 altocumulus01 nova-api[32263]: 2017-03-29 17:46:28.176 32263 ERROR nova   File "/usr/local/lib/python2.7/dist-packages/nova/api/openstack/compute/__init__.py", line 31, in __init__
Mar 29 17:46:28 altocumulus01 nova-api[32263]: 2017-03-29 17:46:28.176 32263 ERROR nova     super(APIRouterV21, self).__init__()
Mar 29 17:46:28 altocumulus01 nova-api[32263]: 2017-03-29 17:46:28.176 32263 ERROR nova   File "/usr/local/lib/python2.7/dist-packages/nova/api/openstack/__init__.py", line 243, in __init__
Mar 29 17:46:28 altocumulus01 nova-api[32263]: 2017-03-29 17:46:28.176 32263 ERROR nova     self._register_resources_check_inherits(mapper)
Mar 29 17:46:28 altocumulus01 nova-api[32263]: 2017-03-29 17:46:28.176 32263 ERROR nova   File "/usr/local/lib/python2.7/dist-packages/nova/api/openstack/__init__.py", line 259, in _register_resources_check_inherits
Mar 29 17:46:28 altocumulus01 nova-api[32263]: 2017-03-29 17:46:28.176 32263 ERROR nova     for resource in ext.obj.get_resources():
Mar 29 17:46:28 altocumulus01 nova-api[32263]: 2017-03-29 17:46:28.176 32263 ERROR nova   File "/usr/local/lib/python2.7/dist-packages/nova/api/openstack/compute/cloudpipe.py", line 187, in get_resources
Mar 29 17:46:28 altocumulus01 nova-api[32263]: 2017-03-29 17:46:28.176 32263 ERROR nova     CloudpipeController())]
Mar 29 17:46:28 altocumulus01 nova-api[32263]: 2017-03-29 17:46:28.176 32263 ERROR nova   File "/usr/local/lib/python2.7/dist-packages/nova/api/openstack/compute/cloudpipe.py", line 48, in __init__
Mar 29 17:46:28 altocumulus01 nova-api[32263]: 2017-03-29 17:46:28.176 32263 ERROR nova     self.setup()
Mar 29 17:46:28 altocumulus01 nova-api[32263]: 2017-03-29 17:46:28.176 32263 ERROR nova   File "/usr/local/lib/python2.7/dist-packages/nova/api/openstack/compute/cloudpipe.py", line 55, in setup
Mar 29 17:46:28 altocumulus01 nova-api[32263]: 2017-03-29 17:46:28.176 32263 ERROR nova     fileutils.ensure_tree(CONF.crypto.keys_path)
Mar 29 17:46:28 altocumulus01 nova-api[32263]: 2017-03-29 17:46:28.176 32263 ERROR nova   File "/usr/local/lib/python2.7/dist-packages/oslo_utils/fileutils.py", line 40, in ensure_tree
Mar 29 17:46:28 altocumulus01 nova-api[32263]: 2017-03-29 17:46:28.176 32263 ERROR nova     os.makedirs(path, mode)
Mar 29 17:46:28 altocumulus01 nova-api[32263]: 2017-03-29 17:46:28.176 32263 ERROR nova   File "/usr/lib/python2.7/os.py", line 157, in makedirs
Mar 29 17:46:28 altocumulus01 nova-api[32263]: 2017-03-29 17:46:28.176 32263 ERROR nova     mkdir(name, mode)
Mar 29 17:46:28 altocumulus01 nova-api[32263]: 2017-03-29 17:46:28.176 32263 ERROR nova OSError: [Errno 13] Permission denied: '/usr/local/lib/python2.7/dist-packages/keys'
Mar 29 17:46:28 altocumulus01 nova-api[32263]: 2017-03-29 17:46:28.176 32263 ERROR nova

